Workbook

Sheet Inputs (English)
A1: Crema Italia · Roaster Pricing Calculator (v1.5)
A2: Blue = your inputs; yellow = the levers. Markup matrix (Store Ops 2.2) or target-margin mode, plus a units-per-order rescue (Section 4). Landed logic mirrors M1 Landed Cost v2 (ML) -> $28.70/kg. US shelf bands from Competitive Price Reference v1 (25 Aug 2026). Includes a private Analysis tab (burdened cost + contribution). Instrument, not a chain model. All figures provisional.
A4: 1 · THE PALLET & THE COFFEE
A5: Pallet net coffee weight | B5: 300 | C5: kg | F5: M1 ML 300 (270-330). ~400 kg not achievable for whole bean on a EUR-1 pallet.
A6: same, US | B6: =B5*2.20462 | C6: lb
A7: Roaster price ← THE LEVER | B7: 18 | C7: EUR / kg | F7: the number under negotiation. M1 range 12-26, ML 18. FCA roastery.
A8: same, per gram | B8: =B7/1000 | C8: EUR / g
A9: EUR to USD rate | B9: 1.1 | C9: USD per EUR | F9: M1 planning ML 1.10 (1.05-1.18). Spot ~1.16 on 3 Sep 2026.
A10: Roaster price (USD) | B10: =B7*B9 | C10: USD / kg
A11: Total coffee value (FOB, EUR) | B11: =B7*B5 | C11: EUR
A12: Total coffee value (FOB / customs value, USD) | B12: =B11*B9 | C12: USD
A14: 2 · THE FOUR BAG SIZES
A15: Bag size | B15: 100 | C15: 250 | D15: 500 | E15: 1000 | F15: grams (blue = editable)
A16: same, US | B16: =B15/28.3495 | C16: =C15/28.3495 | D16: =D15/28.3495 | E16: =E15/28.3495 | F16: oz
A17: Coffee cost / bag (EUR) | B17: =$B7*B15/1000 | C17: =$B7*C15/1000 | D17: =$B7*D15/1000 | E17: =$B7*E15/1000
A18: Coffee cost / bag (USD) | B18: =$B10*B15/1000 | C18: =$B10*C15/1000 | D18: =$B10*D15/1000 | E18: =$B10*E15/1000
A19: Bags per pallet (if all this size) | B19: =$B5*1000/B15 | C19: =$B5*1000/C15 | D19: =$B5*1000/D15 | E19: =$B5*1000/E15
A21: 3 · GET IT TO THE US 3PL SHELF (landed COGS — mirrors M1 v2 ML)
A22: Packaging gross-up factor (cartons) | B22: 1.05 | C22: x net
A23: Pallet & wrap weight | B23: 30 | C23: kg
A24: Chargeable (gross) air weight | B24: =B5*B22+B23 | C24: kg | F24: net + cartons + pallet/wrap; air billed on this. M1 ~344.5 kg.
A25: Air freight rate (marginal, all-in) | B25: 4.35 | C25: USD / kg | F25: M1 ML 4.35 (3.5-6). Fuel + security + terminal included.
A26: Air freight — total | B26: =B24*B25 | C26: USD
A27: Per-shipment fixed (handling, AWB/docs, terminal) | B27: 800 | C27: USD / shpmt | F27: M1 ML 800 (500-1400). Replaces ISF (ocean-only).
A28: Customs broker entry fee | B28: 175 | C28: USD / entry
A29: Inland trucking, port to 3PL | B29: 125 | C29: USD / pallet
A30: 3PL inbound receiving (reference, not summed) | B30: 40 | C30: USD / pallet | F30: M1 books receiving as MONTHLY FIXED, not landed. Excluded so landed matches M1.
A31: Cargo insurance rate | B31: 0.0045 | C31: of goods+frt+fixed
A32: Cargo insurance — total | B32: =B31*(B12+B26+B27) | C32: USD
A33: US import duty (roasted coffee) | B33: 0 | C33: of FOB | F33: HTS 0901.21.00 = FREE. Section 301 forced-labor action could assess 10% - toggle to stress-test.
A34: Duty — total | B34: =B12*B33 | C34: USD
A35: MPF (merchandise processing fee) | B35: =MIN(651.5,MAX(33.58,0.003464*B12)) | C35: USD | F35: 0.3464% of customs value, min $33.58 / max $651.50 (FY2026). HMF is ocean-only (N/A).
A36: Fixed adders / shipment (non-freight) | B36: =B27+B28+B29+B32+B34+B35
A37: All landed adders (freight + fixed) | B37: =B26+B36 | C37: USD / shpmt
A38: Landed adders per sellable kg | B38: =B37/B5 | C38: USD / kg
A39: LANDED COST per kg | B39: =B10+B38 | C39: USD / kg | F39: mirrors M1 v2. At M1 ML inputs = $28.70/kg.
A40: landed cost per gram | B40: =B39/1000 | C40: USD / g
A41: Landed multiple vs FOB | B41: =B39/B10 | C41: x
A43: 4 · PRICING MODE, MARKUP MATRIX & RESCUE
A44: Pricing mode (1 = Markup matrix, 2 = Target gross margin) | B44: 1
...

Sheet Analysis (private)
A1: Analysis (private) · unit economics past landed COGS
A2: Burdened cost and contribution before overhead (labor, taxes, systems). Private - not for the roaster. All figures provisional.
A4: A · RECORD
A5: Roaster | B5: (enter roaster)
A6: Coffee / blend | B6: (enter coffee)
A7: Origin / region | B7: (enter origin)
A8: Roast level | B8: (enter roast level)
A9: Notes | B9: (enter notes)
A11: B · FROM THE NEGOTIATION MODEL
A12: Roaster price | B12: ='Inputs (English)'!B7 | C12: EUR / kg
A13: EUR to USD | B13: ='Inputs (English)'!B9 | C13: USD per EUR
A14: Landed COGS | B14: ='Inputs (English)'!B39 | C14: USD / kg
A15: Basket (units per order) | B15: ='Inputs (English)'!B60 | C15: bags / order
A16: Shelf factors in use (set on Inputs) | B16: ='Inputs (English)'!B51 | C16: 1 Roc 2 Sor 3 Sel 4 Bot
A18: C · FULFILMENT COGS (per order; kit extras are SWAG)
A19: Per-order fulfilment (single bag) | B19: ='Inputs (English)'!B59 | C19: USD / order
A20: Per-bag fulfilment at the basket | B20: ='Inputs (English)'!B62 | C20: USD / bag | F20: single bags use this (basket-amortised).
A21: Kit box / materials | B21: 1.5 | C21: USD / kit | F21: SWAG. Sits in the 2.3 priced base and in cost.
A22: Kit tasting card | B22: 0.5 | C22: USD / kit | F22: SWAG.
A23: Kit assembly labor time | B23: 5 | C23: min / kit | F23: SWAG.
A24: US labor rate | B24: 15 | C24: USD / hr
A25: Kit assembly labor cost | B25: =(B23/60)*B24 | C25: USD / kit
A26: Kit fulfilment (per kit) | B26: ='Inputs (English)'!B59-'Inputs (English)'!B56-'Inputs (English)'!B57+B22+B25 | C26: USD / kit | F26: per-order base, less mailer+insert, plus tasting card + assembly. Box is in the base.
A28: D · SORPRESA KIT BUILD (3 x 100 g)
A29: 3 components landed (this coffee proxy) | B29: ='Inputs (English)'!B39*0.3 | C29: USD / kit | F29: 3 x this coffee's 100 g landed. For a real mixed kit, overwrite with the sum of 3 component costs.
A30: Kit cost base (components + box) | B30: =B29+B21 | C30: USD / kit | F30: the 2.3 priced base.
A31: Sorpresa markup factor | B31: ='Inputs (English)'!B48 | C31: x base | F31: from the matrix (Sorpresa 100 g). Edit on Inputs to test a higher kit markup.
A32: Kit retail (base x factor, 2.3) | B32: =B30*B31 | C32: USD / kit
A34: E · CONTRIBUTION (retail minus burdened, before overhead)
A35: Target contribution % (before overhead) | B35: 0.5 | C35: of retail
A36: Metric | B36: 250 g | C36: 500 g | D36: 1 kg | E36: Sorpresa kit
A37: Retail (matrix / 2.3) | B37: ='Inputs (English)'!C82*'Inputs (English)'!C52 | C37: ='Inputs (English)'!D82*'Inputs (English)'!D52 | D37: ='Inputs (English)'!E82*'Inputs (English)'!E52 | E37: =B32
A38: Landed COGS (coffee) | B38: ='Inputs (English)'!C82 | C38: ='Inputs (English)'!D82 | D38: ='Inputs (English)'!E82 | E38: =B29
A39: Fulfilment + kitting | B39: ='Inputs (English)'!B62 | C39: ='Inputs (English)'!B62 | D39: ='Inputs (English)'!B62 | E39: =B21+B26
A40: Burdened cost | B40: =B38+B39 | C40: =C38+C39 | D40: =D38+D39 | E40: =E38+E39
A41: Contribution $ | B41: =B37-B40 | C41: =C37-C40 | D41: =D37-D40 | E41: =E37-E40
A42: Contribution % | B42: =IF(B37=0,"",(B37-B40)/B37) | C42: =IF(C37=0,"",(C37-C40)/C37) | D42: =IF(D37=0,"",(D37-D40)/D37) | E42: =IF(E37=0,"",(E37-E40)/E37) | F42: red = negative; green = at/above target. Kit uses its own base + kitting cost.
A43: Factor applied | B43: ='Inputs (English)'!C52 | C43: ='Inputs (English)'!D52 | D43: ='Inputs (English)'!E52 | E43: =B31
A45: F · OVERHEAD & BREAK-EVEN (monthly)
A46: Monthly fixed overhead (labor, systems) | B46: ='Inputs (English)'!B63 | C46: USD / month | F46: M1 v2 ML. Income taxes excluded (on net profit, downstream).
...

Sheet Presentation (US)
A2: From your price to the American shelf
A3: What happens to your coffee between your roastery and the American consumer's shelf.
A5: We do not compete with Lavazza or commercial Italian coffee. We compete with American specialty roasters, who campaign on quality and freshness. To get in, our retail price has to stay inside their band. Air freight, the forwarder, customs and the 3PL add real cost, before any markup. US duty on roasted coffee is zero: the cost that matters is the freight.
A8: Your price | B8: ='Inputs (English)'!B7 | C8: EUR / kg | D8: ='Inputs (English)'!B8 | E8: EUR / g
A10: The cost path, by size
A11: Size | B11: Your coffee cost | C11: Landed in the USA | D11: Retail price | E11: Unit price
B12: USD / bag | C12: USD / bag | D12: USD / bag | E12: USD / 100 g
A13: 100 g (3.5 oz) | B13: ='Inputs (English)'!B81 | C13: ='Inputs (English)'!B82 | D13: ='Inputs (English)'!B83 | E13: ='Inputs (English)'!B84
A14: 250 g (8.8 oz) | B14: ='Inputs (English)'!C81 | C14: ='Inputs (English)'!C82 | D14: ='Inputs (English)'!C83 | E14: ='Inputs (English)'!C84
A15: 500 g (17.6 oz) | B15: ='Inputs (English)'!D81 | C15: ='Inputs (English)'!D82 | D15: ='Inputs (English)'!D83 | E15: ='Inputs (English)'!D84
A16: 1 kg (2.2 lb) | B16: ='Inputs (English)'!E81 | C16: ='Inputs (English)'!E82 | D16: ='Inputs (English)'!E83 | E16: ='Inputs (English)'!E84
A18: The American specialty shelf, by size
A19: Size | B19: Our price | C19: US specialty shelf | D19: Source
A20: 250 g single origin | B20: ='Inputs (English)'!$C$83 | C20: =TEXT('Inputs (English)'!B70*2.5,"$0")&" - "&TEXT('Inputs (English)'!C70*2.5,"$0") | D20: Proud Mary, Sey, Passenger
A21: 1 kg | B21: ='Inputs (English)'!$E$83 | C21: =TEXT('Inputs (English)'!B71*10,"$0")&" - "&TEXT('Inputs (English)'!C71*10,"$0") | D21: Verve (2.2 lb)
A22: ="Context (not our shelf): commercial Italian coffee in the USA sells at "&TEXT('Inputs (English)'!B72,"$0.00")&" - "&TEXT('Inputs (English)'!C72,"$0.00")&" / 100 g, with no roast date."
A24: To stay competitive on the American shelf, the price should be at or below:
A25: Target price | B25: ='Inputs (English)'!B102 | C25: EUR / kg
A26: Current price | B26: ='Inputs (English)'!B7 | C26: EUR / kg
A27: Verdict | B27: =IF(ISNUMBER('Inputs (English)'!B102),IF('Inputs (English)'!B7<='Inputs (English)'!B102,"COMPETITIVE","NEEDS A LOWER PRICE"),"no room")
A29: US duty on roasted coffee: 0% (no duty, no quota).
A30: EUR/USD rate used: | B30: ='Inputs (English)'!B9
A31: ="Assumes about "&TEXT('Inputs (English)'!B60,"0")&" bags per order."
A32: Provisional model figures. Metric and US customary shown together.
A34: Crema Italia, LLC · Lutz, Florida, USA · cremaitalia.com

Sheet Presentazione (IT)
A2: Dal vostro prezzo allo scaffale americano
A3: Cosa succede al vostro caffè tra la vostra torrefazione e lo scaffale del consumatore americano.
A5: Non competiamo con Lavazza o con il caffè commerciale italiano. Competiamo con le torrefazioni specialty americane, che campagnano su qualità e freschezza. Per entrare, il nostro prezzo al dettaglio deve restare dentro la loro fascia. Trasporto aereo, spedizioniere, dogana e 3PL aggiungono un costo reale, prima del ricarico. Il dazio USA sul caffè tostato è zero: il costo che conta è il trasporto.
A8: Il vostro prezzo | B8: ='Inputs (English)'!B7 | C8: EUR / kg | D8: ='Inputs (English)'!B8 | E8: EUR / g
A10: Il percorso del costo, per formato
A11: Formato | B11: Vostro costo caffè | C11: Sbarcato in USA | D11: Prezzo al dettaglio | E11: Prezzo unitario
B12: USD / conf. | C12: USD / conf. | D12: USD / conf. | E12: USD / 100 g
A13: 100 g (3.5 oz) | B13: ='Inputs (English)'!B81 | C13: ='Inputs (English)'!B82 | D13: ='Inputs (English)'!B83 | E13: ='Inputs (English)'!B84
A14: 250 g (8.8 oz) | B14: ='Inputs (English)'!C81 | C14: ='Inputs (English)'!C82 | D14: ='Inputs (English)'!C83 | E14: ='Inputs (English)'!C84
A15: 500 g (17.6 oz) | B15: ='Inputs (English)'!D81 | C15: ='Inputs (English)'!D82 | D15: ='Inputs (English)'!D83 | E15: ='Inputs (English)'!D84
A16: 1 kg (2.2 lb) | B16: ='Inputs (English)'!E81 | C16: ='Inputs (English)'!E82 | D16: ='Inputs (English)'!E83 | E16: ='Inputs (English)'!E84
A18: Lo scaffale americano specialty, per formato
A19: Formato | B19: Il nostro prezzo | C19: Scaffale USA specialty | D19: Fonte
A20: 250 g monorigine | B20: ='Inputs (English)'!$C$83 | C20: =TEXT('Inputs (English)'!B70*2.5,"$0")&" - "&TEXT('Inputs (English)'!C70*2.5,"$0") | D20: Proud Mary, Sey, Passenger
A21: 1 kg | B21: ='Inputs (English)'!$E$83 | C21: =TEXT('Inputs (English)'!B71*10,"$0")&" - "&TEXT('Inputs (English)'!C71*10,"$0") | D21: Verve (2.2 lb)
A22: ="Contesto (non il nostro scaffale): il caffè commerciale italiano negli USA vende a "&TEXT('Inputs (English)'!B72,"$0.00")&" - "&TEXT('Inputs (English)'!C72,"$0.00")&" / 100 g, senza data di tostatura."
A24: Per restare competitivi sullo scaffale americano, il prezzo dovrebbe essere pari o inferiore a:
A25: Prezzo obiettivo | B25: ='Inputs (English)'!B102 | C25: EUR / kg
A26: Prezzo attuale | B26: ='Inputs (English)'!B7 | C26: EUR / kg
A27: Verdetto | B27: =IF(ISNUMBER('Inputs (English)'!B102),IF('Inputs (English)'!B7<='Inputs (English)'!B102,"COMPETITIVO","SERVE UN PREZZO PIÙ BASSO"),"nessun margine")
A29: Dazio USA sul caffè tostato: 0% (nessun dazio, nessuna quota).
A30: Cambio EUR/USD usato: | B30: ='Inputs (English)'!B9
A31: ="Ipotesi: circa "&TEXT('Inputs (English)'!B60,"0")&" confezioni per ordine."
A32: Valori provvisori a scopo di modello. Metrico e US customary indicati insieme.
A34: Crema Italia, LLC · Lutz, Florida, USA · cremaitalia.com
